import { Request, Response, NextFunction } from 'express';
import { ZodError } from 'zod';
import logger from '../utils/logger';

export class AppError extends Error {
  statusCode: number;
  isOperational: boolean;

  constructor(message: string, statusCode: number = 500) {
    super(message);
    this.statusCode = statusCode;
    this.isOperational = true;

    Error.captureStackTrace(this, this.constructor);
  }
}

export const errorHandler = (
  err: Error | AppError | ZodError,
  req: Request,
  res: Response,
  next: NextFunction
) => {
  // Log error
  logger.error({
    message: err.message,
    stack: err.stack,
    path: req.path,
    method: req.method,
  });

  // Zod validation errors
  if (err instanceof ZodError) {
    return res.status(400).json({
      success: false,
      error: 'Validation error',
      details: err.issues.map((e: any) => ({
        field: e.path.join('.'),
        message: e.message,
      })),
    });
  }

  // Custom application errors
  if (err instanceof AppError) {
    return res.status(err.statusCode).json({
      success: false,
      error: err.message,
    });
  }

  // Unknown errors - don't expose details in production
  const message =
    process.env.NODE_ENV === 'production'
      ? 'Internal server error'
      : err.message;

  return res.status(500).json({
    success: false,
    error: message,
    ...(process.env.NODE_ENV !== 'production' && { stack: err.stack }),
  });
};

// Async handler wrapper to catch promise rejections
export const asyncHandler = (
  fn: (req: Request, res: Response, next: NextFunction) => Promise<any>
) => {
  return (req: Request, res: Response, next: NextFunction) => {
    Promise.resolve(fn(req, res, next)).catch(next);
  };
};
